Workbook

Sheet Instruction
A1: คำแนะนำการใช้ไฟล์ ใบยืมเงินทดรองจ่าย และสรุปคืนเงินยืม
A2: Guideline : Borrow – Return Money Form
A3: มูลนิธิเพื่อการประเมินเทคโนโลยีและนโยบายด้านสุขภาพ (HITAP) | ฉบับปรับปรุงวันที่ 7 กันยายน 2569 / Revised on 7 September 2026
B5: สัญลักษณ์สีของช่องข้อมูล / Cell colour legend
C6: ช่องสีฟ้า = ช่องกรอกข้อมูล / Blue cell = fill in your information
C7: ช่องสีขาว = สูตรคำนวณ ถูกล็อกไว้ ห้ามแก้ไข / White cell = formula, locked
A9: ส่วนที่ 1 : ขั้นตอนการยืม – คืนเงินทดรองจ่าย (ภาษาไทย) | E9: Section 2 : How to process Borrow – Return Money (English)
B11: 1. การยืมเงินทดรองจ่าย | F11: 1. Borrow money
C12: กรอกรายละเอียดในช่องสีฟ้า ในชีท "ใบยืมเงิน Borrow Money Form" แล้วส่งไฟล์ให้ fin@hitap.net พร้อมเอกสารแนบ ดังนี้ | G12: Fill in the blue cells of the "Borrow Money Form" sheet and send the file to fin@hitap.net together with the following documents:
B13: 1) | C13: ใบยืมเงิน | F13: 1) | G13: Borrow Money Form
B14: 2) | C14: วาระการประชุม (สำหรับการเดินทางไปประชุม) หรือรายละเอียดการลงพื้นที่ | F14: 2) | G14: Meeting agenda (for meetings) or data-collection details
B15: 3) | C15: เอกสารเปรียบเทียบสายการบิน อย่างน้อย 3 สายการบิน (สำหรับการเดินทางไปต่างประเทศ) | F15: 3) | G15: Flight comparison – at least 3 airlines (for international travel)
B16: 4) | C16: หนังสือเชิญประชุม และรายชื่อผู้เข้าร่วมประชุม (ถ้ามี) | F16: 4) | G16: Invitation letter and participant list (if any)
B17: 5) | C17: อัตราแลกเปลี่ยนเงินตราจากธนาคารแห่งประเทศไทย (สำหรับค่าใช้จ่ายต่างประเทศ ถ้ามี) : www.bot.or.th | F17: 5) | G17: Currency exchange rate from Bank of Thailand (for overseas expenses, if any) : www.bot.or.th
B19: 2. การคืนเงินทดรองจ่าย | F19: 2. Return money
B20: 1) | C20: หลังดำเนินกิจกรรมเสร็จ สรุปค่าใช้จ่ายในชีท "สรุปคืนเงินยืมReturn money form" เพื่อเคลียร์เงินยืม | F20: 1) | G20: After the activity, report the expenses in the "Return money form" sheet to clear the borrowed money
B21: 2) | C21: ส่งหลักฐานค่าใช้จ่ายให้ครบถ้วนที่ FIN พร้อมส่งไฟล์ที่กรอกรายละเอียดคืนเงินยืมทดรองที่ fin@hitap.net | F21: 2) | G21: Submit all supporting documents to FIN and send the completed Return money form file to fin@hitap.net
B22: 3) | C22: กรณีไม่มีใบเสร็จรับเงิน/ใบกำกับภาษี (เต็มรูป) กรุณากรอก "ใบสำคัญรับเงิน" แทน | F22: 3) | G22: If there is no receipt / full-form tax invoice, please complete a "Receipt Voucher" instead
B24: 3. การป้องกันการแก้ไขข้อมูลในไฟล์ | F24: 3. Cell protection
B25: • | C25: กรอกข้อมูลได้เฉพาะช่องสีฟ้าเท่านั้น ช่องสีขาวเป็นสูตรคำนวณและถูกล็อกไว้ | F25: • | G25: Only the blue cells can be filled in; white cells are formulas and are locked
B26: • | C26: ชีท "สรุปคืนเงินยืมReturn money form" : หัวตาราง A1:N10 ถูกล็อก ยกเว้น N4 (เลขที่ใบสำคัญจ่าย) | F26: • | G26: "Return money form" sheet : header block A1:N10 is locked, except N4 (Voucher no.)
B27: • | C27: ช่องผลรวม (SUM) และยอดคงเหลือ ถูกล็อกไว้เพื่อป้องกันสูตรเสียหาย | F27: • | G27: The SUM and balance cells are locked to keep the formulas intact
B29: 4. หมายเหตุ | F29: 4. Remarks
B30: • | C30: การประมาณการค่าใช้จ่ายและการสรุปคืนเงิน ช่วยให้ท่านทราบงบประมาณในงานที่รับผิดชอบชัดเจนขึ้น และมีข้อมูล (รายชื่อผู้เข้าร่วมประชุม/ค่าใช้จ่าย) ที่ย้อนกลับมาดูได้เอง โดยไม่ต้องขอค้นเอกสารจากฝ่ายการเงิน | F30: • | G30: Cost estimation and the expense report let you see the budget of the work you are responsible for, and keep a record (participant list / expenses) you can review anytime without requesting documents from FIN
B31: • | C31: ไฟล์นี้เป็น template ท่านปรับขนาดตัวอักษรหรือขนาดคอลัมน์ได้ตามความเหมาะสม แต่ขอความร่วมมือไม่แก้ไขสูตรคำนวณ | F31: • | G31: This file is a template – you may adjust the font or column size as appropriate, but please do not change the formulas
B33: 5. การหักภาษี ณ ที่จ่าย (*ปรึกษาฝ่ายการเงิน) | F33: 5. Withholding tax (*consult FIN)
C34: กรณีจ่ายเงินตั้งแต่ 1,000 บาทขึ้นไป ต้องหักภาษี ณ ที่จ่าย (เฉพาะการจ่ายให้คน/หน่วยงานในประเทศไทย รวมถึงชาวต่างชาติที่มีใบอนุญาตทำงานในไทย หรืออยู่ในไทยเกิน 90 วัน) | G34: If a payment of THB 1,000 or more is made to a Thai person/company – including a foreigner with a Thai work permit or staying in Thailand over 90 days – withholding tax applies as follows:
C35: รายการจ่าย | D35: อัตราหักภาษี | G35: Type of payment | H35: Withholding rate
C36: ค่าตอบแทน | D36: 0.03 | G36: Honorarium | H36: =D36 -> 0.03
C37: ค่าบริการรถตู้ | D37: 0.03 | G37: Van rental | H37: =D37 -> 0.03
C38: ค่าจ้างทำของ | D38: 0.03 | G38: Contract work (ToR) | H38: =D38 -> 0.03
C39: ค่าจ้างทำเสื้อ | D39: 0.03 | G39: Polo shirt production | H39: =D39 -> 0.03
C40: ค่าซื้อซอฟต์แวร์ | D40: 0.03 | G40: Software (Thailand) | H40: =D40 -> 0.03
C41: เงินรางวัล | D41: 0.05 | G41: Award | H41: =D41 -> 0.05
C42: ค่าเช่าสถานที่ / เช่ารถ | D42: 0.05 | G42: Room / car rental | H42: =D42 -> 0.05
C43: ค่าโฆษณาเว็บไซต์ (เช่น JobThai.com) | D43: 0.02 | G43: Website advertising (e.g. JobThai.com) | H43: =D43 -> 0.02
C44: ค่าเบี้ยประกัน (เช่น ประกันอัคคีภัย) | D44: 0.01 | G44: Insurance premium (e.g. fire insurance) | H44: =D44 -> 0.01
C45: ค่าขนส่ง | D45: 0.01 | G45: Transportation | H45: =D45 -> 0.01
B47: สอบถามข้อมูลเพิ่มเติม / For further information : fin@hitap.net

Sheet ใบยืมเงิน Borrow Money Form
H1: ใบเงินยืมทดรองจ่าย | Y1: ที่ / NO.
H2: Request to Borrow Money Form | Y2: วันที่ / Date | AC2: =+TODAY() -> 46292
A3: มูลนิธิเพื่อการประเมินเทคโนโลยีและนโยบายด้านสุขภาพ | AG3: รบกวน save ไฟล์เพื่อนำไปใช้นะคะ
A4: Health Intervention and Technology Assessment Program Foundation
A6: รหัสโครงการ | T6: รหัสกิจกรรม
A7: Project Code | T7: Activity code | AG7: กรอกข้อมูลในช่องสีฟ้าค่ะ
A9: โครงการ(ชื่อย่อ)
A10: Project Name
O12: วันที่ | P12: =+DAY(AC2) -> 27 | R12: เดือน | T12: =+TEXT(AC2,"[$-409]mmmm") -> September | AB12: พ.ศ. | AD12: =YEAR(AC2) -> 2026
O13: Date | R13: Month | AB13: Year
A15: ข้าพเจ้า | S15: ตำแหน่ง
A16: Name | S16: Position
A18: ขออนุมัติยืมเงินทดรองจ่ายเพื่อ
A19: วัตถุประสงค์ / หัวข้อ (ระบุ) Purpose
A21: ระหว่างวันที่ | O21: ถึง | Y21: เวลา
A22: Duration | O22: To | Y22: Time
A24: สถานที่ดำเนินการ
A25: Location
A27: ต้องการรับเงินยืมในวันที่ | N27: (ต้องส่งใบขออนุมัติยืมเงินทดรองจ่ายล่วงหน้า 5-10 วันทำการ)
A28: Date to Receive Money | N28: (request at least 5-10 days before 'Date to Receive Money')
A30: คืนเงินทดรองจ่ายในวันที่ | G30: =+P21+10 -> 10 | N30: กรุณานำส่งหลักฐานการใช้จ่ายเพื่อคืนเงิน (ภายใน 10 วัน หลังสิ้นสุดกิจกรรม)
A31: Date to Return Money | N31: (return money along with financial documents within 10 days
N32: after completion of activitiy)
A33: ต้องการให้เจ้าหน้าที่การเงินช่วยจ่ายเงินในที่ประชุม Do you need a finance officer to help?
A35: ประมาณการค่าใช้จ่ายดังนี้:- Cost estimation as follows:-
A37: รายการ | E37: รายละเอียด | AB37: จำนวนเงิน
A38: Item | E38: Description | AB38: Amount
A39: ค่าตอบแทน
A40: Honorarium
A41: หมายเหตุ (Remark): ค่าตอบแทนจะต้องมีการหักภาษี ณ ที่จ่าย (the withohlding tax will be applied for honorarium)
A42: ค่าเบี้ยเลี้ยง
A43: Per diem
A44: ค่าเครื่องบิน
A45: Airfare
A46: ค่าเดินทาง
A47: Transportation
A48: ค่าที่พัก
A49: Accommodation
A50: ค่าอาหารและเครื่องดื่ม
... A53: Others
...

Sheet สรุปคืนเงินยืมReturn money form
A1: มูลนิธิเพื่อการประเมินเทคโนโลยีและนโยบายด้านสุขภาพ
A2: Health Intervention and Technology Assessment Program Foundation
A3: สรุปคืนเงินยืมทดรองจ่าย / Return money form
A4: =+'ใบยืมเงิน Borrow Money Form'!A6 -> รหัสโครงการ | D4: =+'ใบยืมเงิน Borrow Money Form'!E6 -> 0 | G4: =+'ใบยืมเงิน Borrow Money Form'!T6 -> รหัสกิจกรรม | H4: =+'ใบยืมเงิน Borrow Money Form'!X6 -> 0 | M4: เลขที่ใบสำคัญจ่าย
A5: =+'ใบยืมเงิน Borrow Money Form'!A7 -> Project Code | G5: =+'ใบยืมเงิน Borrow Money Form'!T7 -> Activity code | M5: Voucher no.
A6: โครงการ(ชื่อย่อ) | D6: =+'ใบยืมเงิน Borrow Money Form'!E9 -> 0 | M6: วันที่
A7: Project Name | M7: Date | N7: =+TODAY() -> 46292
A8: วันที่ / Date | D8: =+'ใบยืมเงิน Borrow Money Form'!$G$21 -> 0 | E8: ถึง / To | F8: =+'ใบยืมเงิน Borrow Money Form'!$P$21 -> 0 | H8: เวลา / Time | I8: =+'ใบยืมเงิน Borrow Money Form'!AA21 -> 0
A9: สำหรับ / For | D9: =+'ใบยืมเงิน Borrow Money Form'!G18 -> 0
A10: สถานที่ / Place | D10: =+'ใบยืมเงิน Borrow Money Form'!G24 -> 0
A12: ลำดับ | C12: รายชื่อ | F12: ค่าตอบแทน | G12: ค่าเบี้ยเลี้ยง | H12: ค่าเครื่องบิน | I12: ค่าเดินทาง | J12: ค่าที่พัก | K12: ค่าอาหาร | L12: อื่นๆ | M12: หัก ภาษี ณ ที่จ่าย | N12: รวม
A13: NO. | C13: Name/Description | F13: Honorariam | G13: Perdiem | H13: Airfare | I13: Transportation | J13: Accommodation | K13: Food | L13: Other | M13: Less Withhoding TAX | N13: Total
N14: =SUM(F14:M14) -> 0
N15: =SUM(F15:M15) -> 0
N16: =SUM(F16:M16) -> 0
N17: =SUM(F17:M17) -> 0
N18: =SUM(F18:M18) -> 0
N19: =SUM(F19:M19) -> 0
N20: =SUM(F20:M20) -> 0
N21: =SUM(F21:M21) -> 0
N22: =SUM(F22:M22) -> 0
N23: =SUM(F23:M23) -> 0
N24: =SUM(F24:M24) -> 0
N25: =SUM(F25:M25) -> 0
... N28: =SUM(F28:M28) -> 0
A29: รวมค่าใช้จ่ายทั้งสิ้น | F29: =SUM(F14:F28) -> 0 | G29: =SUM(G14:G28) -> 0 | H29: =SUM(H14:H28) -> 0 | I29: =SUM(I14:I28) -> 0 | J29: =SUM(J14:J28) -> 0 | K29: =SUM(K14:K28) -> 0 | L29: =SUM(L14:L28) -> 0 | M29: =SUM(M14:M28) -> 0 | N29: =SUM(N14:N28) -> 0
A30: SUB TOTAL
A31: หมายเหตุ | M31: เงินยืมทดรองจ่าย | N31: =+'ใบยืมเงิน Borrow Money Form'!AB55 -> 0
A32: Note :- | M32: Amount of money borrowed
M33: คงเหลือเงินคืน / (เบิกเพิ่ม) | N33: =+N31-N29 -> 0
M34: Balance
J36: (ลงชื่อ) | N36: ผู้ยืมเงิน
J37: (Signature) | N37: Payee
K38: =+'ใบยืมเงิน Borrow Money Form'!D63 -> ()
J42: (ลงชื่อ) | N42: ผู้อนุมัติ
J43: (Signature) | N43: Approved
K44: =+'ใบยืมเงิน Borrow Money Form'!T59 -> สุภาพร เอี่ยมอัครเสนา
